{
 "cells": [
  {
   "cell_type": "code",
   "execution_count": 1,
   "id": "ffe4f44a-ccd7-4030-ac26-942bb68ee6ad",
   "metadata": {},
   "outputs": [],
   "source": [
    "import duckdb as ddb"
   ]
  },
  {
   "cell_type": "code",
   "execution_count": 2,
   "id": "bb86dcbe-9d4a-4c62-99a1-330384bdd477",
   "metadata": {},
   "outputs": [],
   "source": [
    "con = ddb.connect(r\"..\\..\\db\\comtrade.duckdb\") \n"
   ]
  },
  {
   "cell_type": "code",
   "execution_count": 3,
   "id": "ff791928-5205-419a-8548-2725f2ad5d1e",
   "metadata": {},
   "outputs": [
    {
     "name": "stdout",
     "output_type": "stream",
     "text": [
      "Traceback (most recent call last):\n",
      "  File \"H:\\conda\\envs\\py312\\Lib\\site-packages\\sqlalchemy\\engine\\base.py\", line 143, in __init__\n",
      "    self._dbapi_connection = engine.raw_connection()\n",
      "                             ^^^^^^^^^^^^^^^^^^^^^^^\n",
      "  File \"H:\\conda\\envs\\py312\\Lib\\site-packages\\sqlalchemy\\engine\\base.py\", line 3301, in raw_connection\n",
      "    return self.pool.connect()\n",
      "           ^^^^^^^^^^^^^^^^^^^\n",
      "  File \"H:\\conda\\envs\\py312\\Lib\\site-packages\\sqlalchemy\\pool\\base.py\", line 447, in connect\n",
      "    return _ConnectionFairy._checkout(self)\n",
      "           ^^^^^^^^^^^^^^^^^^^^^^^^^^^^^^^^\n",
      "  File \"H:\\conda\\envs\\py312\\Lib\\site-packages\\sqlalchemy\\pool\\base.py\", line 1264, in _checkout\n",
      "    fairy = _ConnectionRecord.checkout(pool)\n",
      "            ^^^^^^^^^^^^^^^^^^^^^^^^^^^^^^^^\n",
      "  File \"H:\\conda\\envs\\py312\\Lib\\site-packages\\sqlalchemy\\pool\\base.py\", line 711, in checkout\n",
      "    rec = pool._do_get()\n",
      "          ^^^^^^^^^^^^^^\n",
      "  File \"H:\\conda\\envs\\py312\\Lib\\site-packages\\sqlalchemy\\pool\\impl.py\", line 177, in _do_get\n",
      "    with util.safe_reraise():\n",
      "  File \"H:\\conda\\envs\\py312\\Lib\\site-packages\\sqlalchemy\\util\\langhelpers.py\", line 224, in __exit__\n",
      "    raise exc_value.with_traceback(exc_tb)\n",
      "  File \"H:\\conda\\envs\\py312\\Lib\\site-packages\\sqlalchemy\\pool\\impl.py\", line 175, in _do_get\n",
      "    return self._create_connection()\n",
      "           ^^^^^^^^^^^^^^^^^^^^^^^^^\n",
      "  File \"H:\\conda\\envs\\py312\\Lib\\site-packages\\sqlalchemy\\pool\\base.py\", line 388, in _create_connection\n",
      "    return _ConnectionRecord(self)\n",
      "           ^^^^^^^^^^^^^^^^^^^^^^^\n",
      "  File \"H:\\conda\\envs\\py312\\Lib\\site-packages\\sqlalchemy\\pool\\base.py\", line 673, in __init__\n",
      "    self.__connect()\n",
      "  File \"H:\\conda\\envs\\py312\\Lib\\site-packages\\sqlalchemy\\pool\\base.py\", line 899, in __connect\n",
      "    with util.safe_reraise():\n",
      "  File \"H:\\conda\\envs\\py312\\Lib\\site-packages\\sqlalchemy\\util\\langhelpers.py\", line 224, in __exit__\n",
      "    raise exc_value.with_traceback(exc_tb)\n",
      "  File \"H:\\conda\\envs\\py312\\Lib\\site-packages\\sqlalchemy\\pool\\base.py\", line 895, in __connect\n",
      "    self.dbapi_connection = connection = pool._invoke_creator(self)\n",
      "                                         ^^^^^^^^^^^^^^^^^^^^^^^^^^\n",
      "  File \"H:\\conda\\envs\\py312\\Lib\\site-packages\\sqlalchemy\\engine\\create.py\", line 661, in connect\n",
      "    return dialect.connect(*cargs, **cparams)\n",
      "           ^^^^^^^^^^^^^^^^^^^^^^^^^^^^^^^^^^\n",
      "  File \"H:\\conda\\envs\\py312\\Lib\\site-packages\\duckdb_engine\\__init__.py\", line 301, in connect\n",
      "    conn = duckdb.connect(*cargs, **cparams)\n",
      "           ^^^^^^^^^^^^^^^^^^^^^^^^^^^^^^^^^\n",
      "_duckdb.IOException: IO Error: Cannot open file \"g:\\yandexdisk\\hse\\mgimo-foreign_trade\\db\\comtrade.duckdb\": The process cannot access the file because it is being used by another process.\n",
      "\n",
      "File is already open in \n",
      "H:\\conda\\envs\\py312\\python.exe (PID 51204)\n",
      "\n",
      "The above exception was the direct cause of the following exception:\n",
      "\n",
      "Traceback (most recent call last):\n",
      "  File \"H:\\conda\\envs\\py312\\Lib\\site-packages\\sql\\magic.py\", line 196, in execute\n",
      "    conn = sql.connection.Connection.set(\n",
      "           ^^^^^^^^^^^^^^^^^^^^^^^^^^^^^^\n",
      "  File \"H:\\conda\\envs\\py312\\Lib\\site-packages\\sql\\connection.py\", line 70, in set\n",
      "    cls.current = existing or Connection(descriptor, connect_args, creator)\n",
      "                              ^^^^^^^^^^^^^^^^^^^^^^^^^^^^^^^^^^^^^^^^^^^^^\n",
      "  File \"H:\\conda\\envs\\py312\\Lib\\site-packages\\sql\\connection.py\", line 55, in __init__\n",
      "    self.internal_connection = engine.connect()\n",
      "                               ^^^^^^^^^^^^^^^^\n",
      "  File \"H:\\conda\\envs\\py312\\Lib\\site-packages\\sqlalchemy\\engine\\base.py\", line 3277, in connect\n",
      "    return self._connection_cls(self)\n",
      "           ^^^^^^^^^^^^^^^^^^^^^^^^^^\n",
      "  File \"H:\\conda\\envs\\py312\\Lib\\site-packages\\sqlalchemy\\engine\\base.py\", line 145, in __init__\n",
      "    Connection._handle_dbapi_exception_noconnection(\n",
      "  File \"H:\\conda\\envs\\py312\\Lib\\site-packages\\sqlalchemy\\engine\\base.py\", line 2440, in _handle_dbapi_exception_noconnection\n",
      "    raise sqlalchemy_exception.with_traceback(exc_info[2]) from e\n",
      "  File \"H:\\conda\\envs\\py312\\Lib\\site-packages\\sqlalchemy\\engine\\base.py\", line 143, in __init__\n",
      "    self._dbapi_connection = engine.raw_connection()\n",
      "                             ^^^^^^^^^^^^^^^^^^^^^^^\n",
      "  File \"H:\\conda\\envs\\py312\\Lib\\site-packages\\sqlalchemy\\engine\\base.py\", line 3301, in raw_connection\n",
      "    return self.pool.connect()\n",
      "           ^^^^^^^^^^^^^^^^^^^\n",
      "  File \"H:\\conda\\envs\\py312\\Lib\\site-packages\\sqlalchemy\\pool\\base.py\", line 447, in connect\n",
      "    return _ConnectionFairy._checkout(self)\n",
      "           ^^^^^^^^^^^^^^^^^^^^^^^^^^^^^^^^\n",
      "  File \"H:\\conda\\envs\\py312\\Lib\\site-packages\\sqlalchemy\\pool\\base.py\", line 1264, in _checkout\n",
      "    fairy = _ConnectionRecord.checkout(pool)\n",
      "            ^^^^^^^^^^^^^^^^^^^^^^^^^^^^^^^^\n",
      "  File \"H:\\conda\\envs\\py312\\Lib\\site-packages\\sqlalchemy\\pool\\base.py\", line 711, in checkout\n",
      "    rec = pool._do_get()\n",
      "          ^^^^^^^^^^^^^^\n",
      "  File \"H:\\conda\\envs\\py312\\Lib\\site-packages\\sqlalchemy\\pool\\impl.py\", line 177, in _do_get\n",
      "    with util.safe_reraise():\n",
      "  File \"H:\\conda\\envs\\py312\\Lib\\site-packages\\sqlalchemy\\util\\langhelpers.py\", line 224, in __exit__\n",
      "    raise exc_value.with_traceback(exc_tb)\n",
      "  File \"H:\\conda\\envs\\py312\\Lib\\site-packages\\sqlalchemy\\pool\\impl.py\", line 175, in _do_get\n",
      "    return self._create_connection()\n",
      "           ^^^^^^^^^^^^^^^^^^^^^^^^^\n",
      "  File \"H:\\conda\\envs\\py312\\Lib\\site-packages\\sqlalchemy\\pool\\base.py\", line 388, in _create_connection\n",
      "    return _ConnectionRecord(self)\n",
      "           ^^^^^^^^^^^^^^^^^^^^^^^\n",
      "  File \"H:\\conda\\envs\\py312\\Lib\\site-packages\\sqlalchemy\\pool\\base.py\", line 673, in __init__\n",
      "    self.__connect()\n",
      "  File \"H:\\conda\\envs\\py312\\Lib\\site-packages\\sqlalchemy\\pool\\base.py\", line 899, in __connect\n",
      "    with util.safe_reraise():\n",
      "  File \"H:\\conda\\envs\\py312\\Lib\\site-packages\\sqlalchemy\\util\\langhelpers.py\", line 224, in __exit__\n",
      "    raise exc_value.with_traceback(exc_tb)\n",
      "  File \"H:\\conda\\envs\\py312\\Lib\\site-packages\\sqlalchemy\\pool\\base.py\", line 895, in __connect\n",
      "    self.dbapi_connection = connection = pool._invoke_creator(self)\n",
      "                                         ^^^^^^^^^^^^^^^^^^^^^^^^^^\n",
      "  File \"H:\\conda\\envs\\py312\\Lib\\site-packages\\sqlalchemy\\engine\\create.py\", line 661, in connect\n",
      "    return dialect.connect(*cargs, **cparams)\n",
      "           ^^^^^^^^^^^^^^^^^^^^^^^^^^^^^^^^^^\n",
      "  File \"H:\\conda\\envs\\py312\\Lib\\site-packages\\duckdb_engine\\__init__.py\", line 301, in connect\n",
      "    conn = duckdb.connect(*cargs, **cparams)\n",
      "           ^^^^^^^^^^^^^^^^^^^^^^^^^^^^^^^^^\n",
      "sqlalchemy.exc.OperationalError: (_duckdb.IOException) IO Error: Cannot open file \"g:\\yandexdisk\\hse\\mgimo-foreign_trade\\db\\comtrade.duckdb\": The process cannot access the file because it is being used by another process.\n",
      "\n",
      "File is already open in \n",
      "H:\\conda\\envs\\py312\\python.exe (PID 51204)\n",
      "(Background on this error at: https://sqlalche.me/e/20/e3q8)\n",
      "\n",
      "Connection info needed in SQLAlchemy format, example:\n",
      "               postgresql://username:password@hostname/dbname\n",
      "               or an existing connection: dict_keys([])\n"
     ]
    }
   ],
   "source": [
    "%load_ext sql\n",
    "%sql duckdb:///G:/YandexDisk/HSE/mgimo-foreign_trade/db/comtrade.duckdb"
   ]
  }
 ],
 "metadata": {
  "kernelspec": {
   "display_name": "Python 3 (ipykernel)",
   "language": "python",
   "name": "python3"
  },
  "language_info": {
   "codemirror_mode": {
    "name": "ipython",
    "version": 3
   },
   "file_extension": ".py",
   "mimetype": "text/x-python",
   "name": "python",
   "nbconvert_exporter": "python",
   "pygments_lexer": "ipython3",
   "version": "3.12.3"
  }
 },
 "nbformat": 4,
 "nbformat_minor": 5
}
